Workbook

Sheet Users
A1: ID | B1: ชื่อผู้ใช้ | C1: email | D1: role
A3: 40866b4e | B3: Administrator | C3: serviceticket222@gmail.com | D3: admin
A5: ca8ec9c2 | B5: OnIn | C5: it@dwellled.com | D5: admin
A6: 2089f2b1 | B6: film | C6: nattharikachumnan@gmail.com | D6: admin
A7: 57899c30 | B7: พี่เอ็กซ์ | C7: marketing@dwellled.com | D7: admin
A8: f3619cab | B8: พี่เปา | C8: dr.sales1@dr-ads.com | D8: admin
A9: 1645650e | B9: พี่บอย | C9: serviceteam.ad3@gmail.com | D9: admin

Sheet รายงาน

Sheet Detail233-Samsung-รับเรื่อง
A1: ID | B1: Ref. | C1: แหล่งที่มา | D1: วันเวลาที่รับแจ้ง | E1: เลขที่ติดตามงาน | F1: ลูกค้า | G1: สถานที่/สาขา | H1: สถานที่ตั้ง | I1: ผู้ติดต่อ | J1: เบอร์ติดต่อ | K1: ข้อมูลการรับแจ้ง | L1: รูปภาพที่แจ้ง | M1: MA | N1: ลักษณะงาน | O1: สถานะงาน | P1: ผู้ดำเนินการ | Q1: วันที่นัดหมาย เวลาเริ่มต้น | R1: วันที่นัดหมาย เวลาสิ้นสุด | S1: รายละเอียดการดำเนินการ | T1: ผลการดำเนินการ | U1: เกี่ยวกับอุปกรณ์ | V1: รูปภาพที่ดำเนินการเสร็จแล้ว | W1: วันเวลาเสร็จ | X1: MAP | Y1: วัน/ชั่วโมงที่ใช้ | Z1: ทะเบียนรถ | AA1: หมายเหตุ | AB1: ไฟล์
A2: b6ef2a7f | C2: ไลน์ | D2: 45693.396 | E2: SAM001041 | F2: Samsung | G2: PARAGON | K2: จอร้าน SAMSUNG PARAGON แจ้งจอเม็ดเสียครับ | L2: DataServiceDR_Images/b6ef2a7f.รูปภาพที่แจ้ง.023108.jpg | N2: แก้ไขหน้างาน | O2: รับเรื่อง | W2: 45693.396 | Y2: 0 วัน 0 ชั่วโมง

Sheet Detail228-American Eagle-กำลังด
A1: ID | B1: Ref. | C1: แหล่งที่มา | D1: วันเวลาที่รับแจ้ง | E1: เลขที่ติดตามงาน | F1: ลูกค้า | G1: สถานที่/สาขา | H1: สถานที่ตั้ง | I1: ผู้ติดต่อ | J1: เบอร์ติดต่อ | K1: ข้อมูลการรับแจ้ง | L1: รูปภาพที่แจ้ง | M1: MA | N1: ลักษณะงาน | O1: สถานะงาน | P1: ผู้ดำเนินการ | Q1: วันที่นัดหมาย เวลาเริ่มต้น | R1: วันที่นัดหมาย เวลาสิ้นสุด | S1: รายละเอียดการดำเนินการ | T1: ผลการดำเนินการ | U1: เกี่ยวกับอุปกรณ์ | V1: รูปภาพที่ดำเนินการเสร็จแล้ว | W1: วันเวลาเสร็จ | X1: MAP | Y1: วัน/ชั่วโมงที่ใช้ | Z1: ทะเบียนรถ | AA1: หมายเหตุ | AB1: ไฟล์
A2: cede76a6 | C2: อีเมล์ | D2: 45596.607 | E2: AME000429 | F2: American Eagle | G2: เดอะมอลล์ บางแค | I2: คุณทราย | K2: แบรนด์ AMERICAN EAGLE สาขา เดอะมอลล์ บางแค ***รบกวนอัพโหลดวีดีโอตาม link ด้านล่าง ตามวันที่ที่แจ้งไว้ค่ะ*** In store promotion สำหรับวันที่ 1 - 4 Nov 2024 Link : https://drive.google.com/drive/u/0/folders/1xaOE3PWI99S2JNib7Ru_7WJgxsbAplYP | M2: TRUE | N2: รีโมท | O2: กำลังดำเนินการ | P2: โมชิ | Q2: 45597.615 | R2: 45597.615 | S2: อัพเดตสื่อ | U2: อัพเดทสื่อ | W2: 45596.607 | Y2: 0 วัน 0 ชั่วโมง
A3: d42cc0fc | C3: อีเมล์ | D3: 45596.609 | E3: AME000430 | F3: American Eagle | G3: เดอะมอลล์ บางแค | I3: คุณทราย | K3: In store promotion สำหรับวันที่ 5 - 8 Nov 2024 *** ขอให้ขึ้นวีดีโอภายใน 10 โมง ไม่เลท รบกวนด้วยนะคะ Link : https://drive.google.com/drive/u/0/folders/1QAeyZlRwrxd-prfBRgiXr1Ml_YkK21X_ | M3: TRUE | N3: รีโมท | O3: กำลังดำเนินการ | P3: โมชิ | Q3: 45601.615 | R3: 45601.615 | S3: อัพสื่อ | U3: อัพเดทสื่อ | W3: 45596.609 | Y3: 0 วัน 0 ชั่วโมง
A4: 784c87fe | C4: อีเมล์ | D4: 45596.61 | E4: AME000431 | F4: American Eagle | G4: เดอะมอลล์ บางแค | I4: คุณทราย | K4: In store promotion สำหรับวันที่ 9 - 10 Nov 2024 Link : https://drive.google.com/drive/u/0/folders/1xaOE3PWI99S2JNib7Ru_7WJgxsbAplYP | M4: TRUE | N4: รีโมท | O4: กำลังดำเนินการ | P4: โมชิ | Q4: 45605.612 | R4: 45605.612 | S4: อัพสื่อใหม่ | U4: อัพเดทสื่อ | W4: 45596.61 | Y4: 0 วัน 0 ชั่วโมง
A5: 62094db3 | C5: ไลน์ | D5: 45596.714 | E5: AME000433 | F5: American Eagle | G5: เซ็นทรัลเวิลด์ CTW | I5: คุณทราย | K5: จอไม่ออนไลน์ในระบบ | M5: TRUE | N5: แก้ไขหน้างาน | O5: กำลังดำเนินการ | P5: สนุ๊ก | R5: 45596.737 | S5: เข้าเชื่อมไวไฟ และดึงเข้าระบบ | W5: 45596.714 | Y5: 0 วัน 0 ชั่วโมง

Sheet DataServiceDR
A1: ID | B1: Ref. | C1: แหล่งที่มา | D1: วันเวลาที่รับแจ้ง | E1: เลขที่ติดตามงาน | F1: ลูกค้า | G1: สถานที่/สาขา | H1: สถานที่ตั้ง | I1: ผู้ติดต่อ | J1: เบอร์ติดต่อ | K1: ข้อมูลการรับแจ้ง | L1: รูปภาพที่แจ้ง | M1: MA | N1: ลักษณะงาน | O1: สถานะงาน | P1: ผู้ดำเนินการ | Q1: วันที่นัดหมาย เวลาเริ่มต้น | R1: วันที่นัดหมาย เวลาสิ้นสุด | S1: รายละเอียดการดำเนินการ | T1: ผลการดำเนินการ | U1: เกี่ยวกับอุปกรณ์ | V1: รูปภาพที่ดำเนินการเสร็จแล้ว | W1: วันเวลาเสร็จ | X1: MAP | Y1: วัน/ชั่วโมงที่ใช้ | Z1: ทะเบียนรถ | AA1: หมายเหตุ | AB1: ไฟล์
A2: 1 | C2: ไลน์ | D2: 45533.476 | E2: =UPPER(LEFT(F2,3))&TEXT(COUNTA($F$2:F2),"000000") -> BMN000001 | F2: BMN | G2: ด่านเก็บค่าผ่านทางพิเศษ ด่านสาทร | K2: แผ่นโมดูลสีเพี้ยน | M2: NO | N2: แก้ไขหน้างาน | O2: เรียบร้อยปกติ | P2: โมชิ | U2: Module | W2: 45535.917 | Y2: =ROUND(IF(ISBLANK(W2), (NOW() - D2) * 24 / 24, (W2 - D2) * 24 / 24), 2) & " วัน " & ROUND(MOD(IF(ISBLANK(W2), (NOW() - D2) * 24, (W2 - D2) * 24), 24), 2) & " ชั่วโมง" -> 2.44 วัน 10.57 ชั่วโมง
A3: 2 | C3: ไลน์ | D3: 45533.476 | E3: =UPPER(LEFT(F3,3))&TEXT(COUNTA($F$2:F3),"000000") -> BMN000002 | F3: BMN | G3: ด่านเก็บค่าผ่านทางพิเศษ ด่านสาทร | K3: แผ่นโมดูลสีเพี้ยน | M3: NO | N3: แก้ไขหน้างาน | O3: เรียบร้อยปกติ | P3: โมชิ | S3: รบกวนทำใบเสนอราคา 1.ช่าง 2.แผ่นโมดู | T3: เปลี่ยนแผ่นโมดูล 1 แผ่น | U3: Module | W3: 45535.917 | Y3: =ROUND(IF(ISBLANK(W3), (NOW() - D3) * 24 / 24, (W3 - D3) * 24 / 24), 2) & " วัน " & ROUND(MOD(IF(ISBLANK(W3), (NOW() - D3) * 24, (W3 - D3) * 24), 24), 2) & " ชั่วโมง" -> 2.44 วัน 10.57 ชั่วโมง
A4: 3 | C4: ไลน์ | D4: 45547 | E4: =UPPER(LEFT(F4,3))&TEXT(COUNTA($F$2:F4),"000000") -> BMN000003 | F4: BMN | G4: ด่านเก็บค่าผ่านทางพิเศษ ด่านอโศก 3 | K4: จอดับทุกจอ | M4: YES | N4: แก้ไขหน้างาน | O4: เรียบร้อยปกติ | S4: ฟิวส์ขาด | T4: เปลี่ี่ยนฟิวส์ | U4: Sending | W4: 45538.604 | Y4: =ROUND(IF(ISBLANK(W4), (NOW() - D4) * 24 / 24, (W4 - D4) * 24 / 24), 2) & " วัน " & ROUND(MOD(IF(ISBLANK(W4), (NOW() - D4) * 24, (W4 - D4) * 24), 24), 2) & " ชั่วโมง" -> -8.4 วัน 14.5 ชั่วโมง
A5: 4 | C5: ไลน์ | D5: 45540.466 | E5: =UPPER(LEFT(F5,3))&TEXT(COUNTA($F$2:F5),"000000") -> BMN000004 | F5: BMN | G5: ด่านประชาชื่นขาออก | K5: จอดับทุกจอ | M5: YES | N5: แก้ไขหน้างาน | O5: เรียบร้อยปกติ | S5: ตรวจสอบหัวแลนไม่มีสัญญาณ | T5: ย้ำหัวแลนใหม่ | U5: Sending | W5: 45540.667 | Y5: =ROUND(IF(ISBLANK(W5), (NOW() - D5) * 24 / 24, (W5 - D5) * 24 / 24), 2) & " วัน " & ROUND(MOD(IF(ISBLANK(W5), (NOW() - D5) * 24, (W5 - D5) * 24), 24), 2) & " ชั่วโมง" -> 0.2 วัน 4.82 ชั่วโมง
A6: 5 | C6: ไลน์ | D6: 45543.36 | E6: =UPPER(LEFT(F6,3))&TEXT(COUNTA($F$2:F6),"000000") -> BMN000005 | F6: BMN | G6: ด่านเก็บค่าผ่านทางพิเศษ ด่านอโศก 3 | K6: จอดับทุกจอ | M6: YES | N6: แก้ไขหน้างาน | O6: เรียบร้อยปกติ | S6: โปรเซสเซอร์ขึ้น No input ตรวจสอบพบ Player ดับ | T6: ทำการเสียบปลั๊กใหม่ | U6: Sending | W6: 45543.601 | Y6: =ROUND(IF(ISBLANK(W6), (NOW() - D6) * 24 / 24, (W6 - D6) * 24 / 24), 2) & " วัน " & ROUND(MOD(IF(ISBLANK(W6), (NOW() - D6) * 24, (W6 - D6) * 24), 24), 2) & " ชั่วโมง" -> 0.24 วัน 5.77 ชั่วโมง | AA6: 1. เดินทางมาถึงพบว่าจอติดปกติ (ทีมไวร์เออมาถึงก่อน) 2.สอบถามทีมไวร์เออ แจ้งว่า โปรเซสเซอร์ขึ้น No input ตรวจสอบแล้ว playerดับ เปิดplayer จอติดปกติครับ
A7: 6 | C7: ไลน์ | D7: 45472 | E7: =UPPER(LEFT(F7,3))&TEXT(COUNTA($F$2:F7),"000000") -> BMN000006 | F7: BMN | G7: สถานีจตุจักร จอ Column ฝั่ง NE | K7: แจ้งซ่อมจอสื่อ สถานีสวนจตุจักร(BL13)ดับ 1จุด ขั้นออกบัตรโดยสาร หน้าห้องSOR ทางออกประตู1,4 ครับ | M7: YES | N7: แก้ไขหน้างาน | O7: เรียบร้อยปกติ | P7: เหน่ง, เคี้ยง | S7: เข้าแก้ไขจอกล่อง Digital Column แผ่นโมตูลดับบางส่วน | T7: เปลี่ยนการ์ด 1 จุด เปลี่ยนสายlen 1 เส้น | U7: Recive | W7: 45544.562 | Y7: =ROUND(IF(ISBLANK(W7), (NOW() - D7) * 24 / 24, (W7 - D7) * 24 / 24), 2) & " วัน " & ROUND(MOD(IF(ISBLANK(W7), (NOW() - D7) * 24, (W7 - D7) * 24), 24), 2) & " ชั่วโมง" -> 72.56 วัน 13.5 ชั่วโมง | AA7: เข้าครั้งที่1. MANPOWER : เหน่ง กร ทะเบียนรถ : 3221 วันเวลาเริ่ม : 29/6/2024 13.00 น. วันเวลาเสร็จ : 1/7/2024 16.00 น. ผลการตรวจสอบ : 1.ตรวจวัด กระแสV ได้ 8.1V (หม้อแปลงเสีย) 2.เปลี่ยนหม้อแปลง 350-5V 1ใบ 3.เปิดจอแล้วแผ่นยังไม่ติด 4.ทดลองสลับการ์ดแล้วไม่ติด 5.นำสายแพรไปเสียบการ์ดตัวอื่นติด 6.นำสายแพรแผ่นที่ติดมาเสียบการ์ดที่เปลี่ยนหม้อแปลงผลปรากฏว่าแผ่นไม่ติด วิธีแก้ไข : ไม่สามารถแก้ไขได้ครับ ผู้ติดต่อ : >ช่างแก้ไขระบุ เบอร์โทร : >ช่างแก้ไขระบุ สถานะแก้ไข : Process ------------------------------------- เข้าครั้งที่2. งาน : แก้ไข กลุ่มบริษัทลูกค้า : BMN วันเวลานัดหมาย : 1/7/2024 15:00-16:00 สถานที่ : เซนทรัลชิดลม ที่สถานีจตุจักร บริเวณ Concourse ฝั่ง NE ข้อมูลการรับแจ้ง : เแผ่นโมดูลดับบางส่วน ##################################### MANPOWER : พี่จ่อย,สาวหยาง ทะเบียนรถ : 3221 วันเวลาเริ่ม : 1/7/2024 13.00 น. วันเวลาเสร็จ : 1/7/2024 16.00 น. ผลการตรวจสอบ : พบการ์ดเสีย 1 ใบ และสายแลนเสีย 1 เส้น วิธีแก้ไข : เปลี่ยนการ์ด 1 จุด เปลี่ยนสายlen 1 เส้น ผู้ติดต่อ : >ช่างแก้ไขระบุ เบอร์โทร : >ช่างแก้ไขระบุ สถานะแก้ไข : Close หมายเหตุ : พิกัด : แนบรูปหน้างาน
A8: 7 | C8: ไลน์ | D8: 45473.625 | E8: =UPPER(LEFT(F8,3))&TEXT(COUNTA($F$2:F8),"000000") -> BMN000007 | F8: BMN | G8: MRT เพชรบุรี | K8: แก้ไขกล่องไฟไดนามิกดับ3กล่อง | M8: YES | N8: แก้ไขหน้างาน | O8: เรียบร้อยปกติ | P8: เหน่ง, เคี้ยง | S8: สาเหตุลูกค้าปิดสวิทย์คันโยกทั้ง3กล่อง | T8: ทำการยกสวิทย์คันโยกเครื่องใช้งานได้ปกติ | U8: Sending | W8: 45474.625 | Y8: =ROUND(IF(ISBLANK(W8), (NOW() - D8) * 24 / 24, (W8 - D8) * 24 / 24), 2) & " วัน " & ROUND(MOD(IF(ISBLANK(W8), (NOW() - D8) * 24, (W8 - D8) * 24), 24), 2) & " ชั่วโมง" -> 1 วัน 0 ชั่วโมง
A9: 8 | C9: ไลน์ | D9: 45474.475 | E9: =UPPER(LEFT(F9,3))&TEXT(COUNTA($F$2:F9),"000000") -> BMN000008 | F9: BMN | G9: สถานีเพชรบุรี จอColumn ด้านหลังจอ Wellcome | K9: จอไดนามิกดับ | M9: YES | N9: แก้ไขหน้างาน | O9: เรียบร้อยปกติ | P9: วิรชน สมร_จ่อย | S9: สายไฟ DC เสีย 1 เส้น | T9: ทำการเเก้ใขเปลี่ยนสายDCใหม่ 1 เส้น | U9: Sending | W9: 45474.667 | Y9: =ROUND(IF(ISBLANK(W9), (NOW() - D9) * 24 / 24, (W9 - D9) * 24 / 24), 2) & " วัน " & ROUND(MOD(IF(ISBLANK(W9), (NOW() - D9) * 24, (W9 - D9) * 24), 24), 2) & " ชั่วโมง" -> 0.19 วัน 4.6 ชั่วโมง
A10: 9 | C10: ไลน์ | D10: 45474 | E10: =UPPER(LEFT(F10,3))&TEXT(COUNTA($F$2:F10),"000000") -> BMN000009 | F10: BMN | G10: ตอม่อแยกประดิพัพท์ | K10: จอ LED มีแผ่นโมดูลดับ 1 แผ่น | M10: YES | N10: แก้ไขหน้างาน | O10: เรียบร้อยปกติ | P10: ส่าวหย่าง | S10: แผ่นโมดูลเสีย จำนวน 1 แผ่น | T10: เปลี่ยนแผ่นใหม่จำนวน 1 แผ่น | U10: Module | W10: 45474.667 | Y10: =ROUND(IF(ISBLANK(W10), (NOW() - D10) * 24 / 24, (W10 - D10) * 24 / 24), 2) & " วัน " & ROUND(MOD(IF(ISBLANK(W10), (NOW() - D10) * 24, (W10 - D10) * 24), 24), 2) & " ชั่วโมง" -> 0.67 วัน 16 ชั่วโมง
A11: 10 | C11: ไลน์ | D11: 45545 | E11: =UPPER(LEFT(F11,3))&TEXT(COUNTA($F$2:F11),"000000") -> RIC000010 | F11: Ricco | G11: Adidas เซ็นทรัล พัทยา | K11: ฝากเปลี่ยนสื่อในอีกโปรแกรม จอ 21.5นิ้ว สาขา CRC Pattaya ให้หน่อย ครับ เล่นแทนสื่อเก่า เปลี่ยนได้เลยครับ | M11: YES | N11: รีโมท | O11: เรียบร้อยปกติ | P11: ฟลุ๊ค | S11: อัพสื่อ | T11: อัพสื่อเรียบร้อย | U11: Sending | W11: 45545.674 | Y11: =ROUND(IF(ISBLANK(W11), (NOW() - D11) * 24 / 24, (W11 - D11) * 24 / 24), 2) & " วัน " & ROUND(MOD(IF(ISBLANK(W11), (NOW() - D11) * 24, (W11 - D11) * 24), 24), 2) & " ชั่วโมง" -> 0.67 วัน 16.17 ชั่วโมง
A12: 11 | C12: ไลน์ | D12: 45537 | E12: =UPPER(LEFT(F12,3))&TEXT(COUNTA($F$2:F12),"000000") -> VES000011 | F12: Vespa | G12: เวสป้าบางแค | K12: เปลี่ยนจอ Kiosk | M12: YES | N12: แก้ไขหน้างาน | O12: เรียบร้อยปกติ | P12: หนูเล็ก | S12: เปลี่ยนจอ Kiosk 43นิ้ว ทัช จำนวน 1 จอ โดยเปลี่ยนใช้ Box เดิมของหน้าสาขา | T12: เปลี่ยนจอ Kiosk 43นิ้ว ทัช จำนวน 1 จอ โดยเปลี่ยนใช้ Box เดิมของหน้าสาขา | U12: Panel | W12: 45537.611 | Y12: =ROUND(IF(ISBLANK(W12), (NOW() - D12) * 24 / 24, (W12 - D12) * 24 / 24), 2) & " วัน " & ROUND(MOD(IF(ISBLANK(W12), (NOW() - D12) * 24, (W12 - D12) * 24), 24), 2) & " ชั่วโมง" -> 0.61 วัน 14.67 ชั่วโมง
A13: 12 | C13: ไลน์ | D13: 45537 | E13: =UPPER(LEFT(F13,3))&TEXT(COUNTA($F$2:F13),"000000") -> WOR000012 | F13: Workzone | G13: Workzone | K13: ส่งจอ Monitor 32นิ้ว จำนวน 2 จอ Monitor 21.5 นิ้ว= 2 จอ | M13: YES | N13: แก้ไขหน้างาน | O13: เรียบร้อยปกติ | P13: ณัฐวุฒิ อรรถประจง_โอ๋ | S13: ส่งจอ Monitor 32นิ้ว จำนวน 2 จอ Monitor 21.5 นิ้ว= 2 จอ | T13: Qc จอกับลูกเรียบร้อยเเละส่งครับ | U13: Panel | W13: 45537.642 | Y13: =ROUND(IF(ISBLANK(W13), (NOW() - D13) * 24 / 24, (W13 - D13) * 24 / 24), 2) & " วัน " & ROUND(MOD(IF(ISBLANK(W13), (NOW() - D13) * 24, (W13 - D13) * 24), 24), 2) & " ชั่วโมง" -> 0.64 วัน 15.42 ชั่วโมง
A14: 13 | C14: ไลน์ | D14: 45534 | E14: =UPPER(LEFT(F14,3))&TEXT(COUNTA($F$2:F14),"000000") -> EVE000013 | F14: EVEANDBOY | G14: เมเจอร์ ปิ่นเกล้า | K14: ติดตั้งจอล้อมเสา | M14: YES | N14: แก้ไขหน้างาน | O14: เรียบร้อยปกติ | P14: ณัฐวุฒิ อรรถประจง_โอ๋ | S14: ติดตั้งจอล้อมเสา | T14: เรียบร้อย | U14: Module | W14: 45537.708 | Y14: =ROUND(IF(ISBLANK(W14), (NOW() - D14) * 24 / 24, (W14 - D14) * 24 / 24), 2) & " วัน " & ROUND(MOD(IF(ISBLANK(W14), (NOW() - D14) * 24, (W14 - D14) * 24), 24), 2) & " ชั่วโมง" -> 3.71 วัน 17 ชั่วโมง
A15: 14 | B15: 7304563 | C15: ไลน์ | D15: 45532.495 | E15: =UPPER(LEFT(F15,3))&TEXT(COUNTA($F$2:F15),"000000") -> TRU000014 | F15: TRUE | G15: True Shop Central Plaza Udonthani | I15: พลอยไพลิน | J15: 0966466694 | K15: จอดับบางส่วน | M15: YES | N15: รีโมท | O15: เรียบร้อยปกติ | P15: ปรีชา ภูตานันท์_ชาสลิม, ชินาธิป สุขรูป_เณน | S15: เกิดจากการกล่องควบคุมจอค้าง | T15: สั่ง ปิด เปิด กล่องผ่านระบบ online ให้ลูกค้าใหม่ | U15: Module | W15: 45532.495 | Y15: =ROUND(IF(ISBLANK(W15), (NOW() - D15) * 24 / 24, (W15 - D15) * 24 / 24), 2) & " วัน " & ROUND(MOD(IF(ISBLANK(W15), (NOW() - D15) * 24, (W15 - D15) * 24), 24), 2) & " ชั่วโมง" -> 0 วัน 0 ชั่วโมง | AB15: TR0013
A16: 15 | B16: 7309348 | C16: ไลน์ | D16: 45531.538 | E16: =UPPER(LEFT(F16,3))&TEXT(COUNTA($F$2:F16),"000000") -> TRU000015 | F16: TRUE | G16: True Shop Central Chanthaburi | I16: แคทรียา | J16: 0839789897 | K16: สื่อไม่อัพเดทสาขายังพบปัญหาจอสลับเหมือนเดิม | M16: YES | N16: รีโมท | O16: เรียบร้อยปกติ | P16: โมชิ | S16: เกิดจากการขึ้นสื่อผิดจอขิงทีมขึ้นสื่อเนื่องจากเป็นการเพิ่มสินค้าภายหลัง ทำให้การระบุจอ ซ้าย ขวา กลางผิดพลาด | T16: สลับสื่อขึ้นจอให้ลูกค้าใหม่ | U16: แก้ไขสื่อ | W16: 45531.538 | Y16: =ROUND(IF(ISBLANK(W16), (NOW() - D16) * 24 / 24, (W16 - D16) * 24 / 24), 2) & " วัน " & ROUND(MOD(IF(ISBLANK(W16), (NOW() - D16) * 24, (W16 - D16) * 24), 24), 2) & " ชั่วโมง" -> 0 วัน 0 ชั่วโมง | AB16: TR0014
A17: 16 | B17: 7309518 | C17: ไลน์ | D17: 45531.542 | E17: =UPPER(LEFT(F17,3))&TEXT(COUNTA($F$2:F17),"000000") -> TRU000016 | F17: TRUE | G17: True Shop Terminal 21 | I17: Chutima | J17: 0955965646 | K17: สื่อไม่อัพเดทสื่อขึ้นสลับฝั่ง | M17: YES | N17: รีโมท | O17: เรียบร้อยปกติ | P17: โมชิ | S17: เกิดจากการจัดชั้นวางสินค้าซ้าย ขวา ของทางหน้าร้าน กับทีมขึันสื่อเรา เนื่องจากไม่มีรูปประกอบ ตั้งแต่แรกที่มีแจ้งเพิ่มสินค้าในชั้นวาง | T17: สลับสื่อขึ้นจอให้ลูกค้าใหม่ | U17: แก้ไขสื่อ | W17: 45531.542 | Y17: =ROUND(IF(ISBLANK(W17), (NOW() - D17) * 24 / 24, (W17 - D17) * 24 / 24), 2) & " วัน " & ROUND(MOD(IF(ISBLANK(W17), (NOW() - D17) * 24, (W17 - D17) * 24), 24), 2) & " ชั่วโมง" -> 0 วัน 0 ชั่วโมง | AB17: TR0015
A18: 17 | B18: 7312801 | C18: ไลน์ | D18: 45536.465 | E18: =UPPER(LEFT(F18,3))&TEXT(COUNTA($F$2:F18),"000000") -> TRU000017 | F18: TRUE | G18: True Branding Shop True Tower 1 | I18: นันทวัน | J18: 0970974560 | K18: สื่อไม่อัพเดทจอทีวี Marketing สื่อไม่ขึ้น 2 จอ จอด้านซ้าย และจอกลาง รบกวนให้เจ้าหน้าที่ช่วยแก้ไขด่วนด้วยครับ | M18: YES | N18: รีโมท | O18: เรียบร้อยปกติ | P18: โมชิ | S18: เกิดจากการจัดชั้นวางสินค้าซ้าย ขวา ของทางหน้าร้าน กับทีมขึันสื่อเรา เนื่องจากไม่มีรูปประกอบ ตั้งแต่แรกที่มีแจ้งเพิ่มสินค้าในชั้นวาง | T18: สลับสื่อขึ้นจอให้ลูกค้าใหม่ | U18: แก้ไขสื่อ | W18: 45536.465 | Y18: =ROUND(IF(ISBLANK(W18), (NOW() - D18) * 24 / 24, (W18 - D18) * 24 / 24), 2) & " วัน " & ROUND(MOD(IF(ISBLANK(W18), (NOW() - D18) * 24, (W18 - D18) * 24), 24), 2) & " ชั่วโมง" -> 0 วัน 0 ชั่วโมง | AB18: TR0016
A19: 18 | B19: 7317121 | C19: ไลน์ | D19: 45536.423 | E19: =UPPER(LEFT(F19,3))&TEXT(COUNTA($F$2:F19),"000000") -> TRU000018 | F19: TRUE | G19: True Shop Central Rama 9 | I19: สุพัตรา | J19: 0842988898 | K19: จอดับบางส่วน | M19: YES | N19: รีโมท | O19: เรียบร้อยปกติ | P19: โมชิ | S19: เกิดจากการตั้งกำหนดเวลาเล่นสื่อของทีมขึ้นสื่อ คือตั้งกำหนดหมดอายุ สิ้นเดือน สิงหาคม | T19: ยกเลิกกำหนดเวลาในโปรแกรม และส่งสื่อขึ้นจอให้ใหม่ | U19: แก้ไขสื่อ | W19: 45536.423 | Y19: =ROUND(IF(ISBLANK(W19), (NOW() - D19) * 24 / 24, (W19 - D19) * 24 / 24), 2) & " วัน " & ROUND(MOD(IF(ISBLANK(W19), (NOW() - D19) * 24, (W19 - D19) * 24), 24), 2) & " ชั่วโมง" -> 0 วัน 0 ชั่วโมง | AB19: TR0017
A20: 19 | B20: 7317169 | C20: ไลน์ | D20: 45537 | E20: =UPPER(LEFT(F20,3))&TEXT(COUNTA($F$2:F20),"000000") -> TRU000019 | F20: TRUE | G20: True Shop Robinson Roiet | I20: Thanayut | J20: 0955544450 | K20: จอดับบางส่วน จอโฆษณา Accessories ดับ จอไม่แสดงสื่อโฆษณา | M20: YES | N20: รีโมท | O20: เรียบร้อยปกติ | P20: โมชิ | S20: เกิดจากการตั้งกำหนดเวลาเล่นสื่อของทีมขึ้นสื่อ คือตั้งกำหนดหมดอายุ สิ้นเดือน สิงหาคม | T20: ยกเลิกกำหนดเวลาในโปรแกรม และส่งสื่อขึ้นจอให้ใหม่ | U20: แก้ไขสื่อ | W20: 45537.423 | Y20: =ROUND(IF(ISBLANK(W20), (NOW() - D20) * 24 / 24, (W20 - D20) * 24 / 24), 2) & " วัน " & ROUND(MOD(IF(ISBLANK(W20), (NOW() - D20) * 24, (W20 - D20) * 24), 24), 2) & " ชั่วโมง" -> 0.42 วัน 10.15 ชั่วโมง | AB20: TR0018
A21: 20 | B21: 7317157 | C21: ไลน์ | D21: 45536.424 | E21: =UPPER(LEFT(F21,3))&TEXT(COUNTA($F$2:F21),"000000") -> TRU000020 | F21: TRUE | G21: True Shop Emquartier | I21: Narttaya | J21: 0956619797 | K21: จอดับบางส่วน หน้าจอเปิด ไม่ติด รบกวนหน่วยงานตรวจสอบและแก้ไข จอ ให้ด้วยค่ะ ขึ้นจอดำ | M21: YES | N21: รีโมท | O21: เรียบร้อยปกติ | P21: โมชิ | S21: เกิดจากการตั้งกำหนดเวลาเล่นสื่อของทีมขึ้นสื่อ คือตั้งกำหนดหมดอายุ สิ้นเดือน สิงหาคม | T21: ยกเลิกกำหนดเวลาในโปรแกรม และส่งสื่อขึ้นจอให้ใหม่ | U21: แก้ไขสื่อ | W21: 45536.424 | Y21: =ROUND(IF(ISBLANK(W21), (NOW() - D21) * 24 / 24, (W21 - D21) * 24 / 24), 2) & " วัน " & ROUND(MOD(IF(ISBLANK(W21), (NOW() - D21) * 24, (W21 - D21) * 24), 24), 2) & " ชั่วโมง" -> 0 วัน 0 ชั่วโมง | AB21: TR0019
A22: 21 | B22: 7317168 | C22: ไลน์ | D22: 45536.427 | E22: =UPPER(LEFT(F22,3))&TEXT(COUNTA($F$2:F22),"000000") -> TRU000021 | F22: TRUE | G22: True Shop Central Chonburi | I22: Arnont | J22: 0909042570/0918269964 | K22: จอดับบางส่วน หน้าจอเปิด ไม่ติด จอ TV Corner 3 จอเปิดไม่ติด ไม่มีสื่อ รูปภาพตามไฟล์แนบ | M22: YES | N22: รีโมท | O22: เรียบร้อยปกติ | P22: โมชิ | S22: เกิดจากการตั้งกำหนดเวลาเล่นสื่อของทีมขึ้นสื่อ คือตั้งกำหนดหมดอายุ สิ้นเดือน สิงหาคม | T22: ยกเลิกกำหนดเวลาในโปรแกรม และส่งสื่อขึ้นจอให้ใหม่ | U22: แก้ไขสื่อ | W22: 45536.427 | Y22: =ROUND(IF(ISBLANK(W22), (NOW() - D22) * 24 / 24, (W22 - D22) * 24 / 24), 2) & " วัน " & ROUND(MOD(IF(ISBLANK(W22), (NOW() - D22) * 24, (W22 - D22) * 24), 24), 2) & " ชั่วโมง" -> 0 วัน 0 ชั่วโมง | AB22: TR0020
A23: 22 | B23: 7317171 | C23: ไลน์ | D23: 45536.428 | E23: =UPPER(LEFT(F23,3))&TEXT(COUNTA($F$2:F23),"000000") -> TRU000022 | F23: TRUE | G23: True Shop Central Plaza Ramindra | I23: Chayapon | J23: 0809719995 | K23: จอดับบางส่วน หน้าจอเปิด ไม่ติด | M23: YES | N23: รีโมท | O23: เรียบร้อยปกติ | P23: โมชิ | S23: เกิดจากการตั้งกำหนดเวลาเล่นสื่อของทีมขึ้นสื่อ คือตั้งกำหนดหมดอายุ สิ้นเดือน สิงหาคม | T23: ยกเลิกกำหนดเวลาในโปรแกรม และส่งสื่อขึ้นจอให้ใหม่ | U23: แก้ไขสื่อ | W23: 45536.428 | Y23: =ROUND(IF(ISBLANK(W23), (NOW() - D23) * 24 / 24, (W23 - D23) * 24 / 24), 2) & " วัน " & ROUND(MOD(IF(ISBLANK(W23), (NOW() - D23) * 24, (W23 - D23) * 24), 24), 2) & " ชั่วโมง" -> 0 วัน 0 ชั่วโมง | AB23: TR0021
A24: 23 | B24: 7317181 | C24: ไลน์ | D24: 45536.434 | E24: =UPPER(LEFT(F24,3))&TEXT(COUNTA($F$2:F24),"000000") -> TRU000023 | F24: TRUE | G24: True Shop Central Plaza Ramindra | I24: Supapron | J24: 0955655445 | M24: YES | N24: รีโมท | O24: เรียบร้อยปกติ | P24: โมชิ | S24: เกิดจากการตั้งกำหนดเวลาเล่นสื่อของทีมขึ้นสื่อ คือตั้งกำหนดหมดอายุ สิ้นเดือน สิงหาคม | T24: ยกเลิกกำหนดเวลาในโปรแกรม และส่งสื่อขึ้นจอให้ใหม่ | U24: แก้ไขสื่อ | W24: 45536.434 | Y24: =ROUND(IF(ISBLANK(W24), (NOW() - D24) * 24 / 24, (W24 - D24) * 24 / 24), 2) & " วัน " & ROUND(MOD(IF(ISBLANK(W24), (NOW() - D24) * 24, (W24 - D24) * 24), 24), 2) & " ชั่วโมง" -> 0 วัน 0 ชั่วโมง | AB24: TR0022
A25: 24 | B25: 7317196 | C25: ไลน์ | D25: 45536.437 | E25: =UPPER(LEFT(F25,3))&TEXT(COUNTA($F$2:F25),"000000") -> TRU000024 | F25: TRUE | G25: True Branding Shop Siam Square Soi 2 | I25: กฤตวิทย์ | J25: 0645269192 | K25: สื่อไม่อัพเดทจอ TV ไม่ทำการโชว์สื่อ | M25: YES | N25: รีโมท | O25: เรียบร้อยปกติ | P25: โมชิ | S25: เกิดจากการตั้งกำหนดเวลาเล่นสื่อของทีมขึ้นสื่อ คือตั้งกำหนดหมดอายุ สิ้นเดือน สิงหาคม | T25: ยกเลิกกำหนดเวลาในโปรแกรม และส่งสื่อขึ้นจอให้ใหม่ | U25: แก้ไขสื่อ | W25: 45536.437 | Y25: =ROUND(IF(ISBLANK(W25), (NOW() - D25) * 24 / 24, (W25 - D25) * 24 / 24), 2) & " วัน " & ROUND(MOD(IF(ISBLANK(W25), (NOW() - D25) * 24, (W25 - D25) * 24), 24), 2) & " ชั่วโมง" -> 0 วัน 0 ชั่วโมง | AB25: TR0023
A26: 25 | B26: 7317230 | C26: ไลน์ | D26: 45536.444 | E26: =UPPER(LEFT(F26,3))&TEXT(COUNTA($F$2:F26),"000000") -> TRU000025 | F26: TRUE | G26: True Shop Central Plaza Udonthani | I26: ศิริขวัญ | J26: 0644199966 | K26: จอดับบางส่วน หน้าจอเปิด ไม่ติด | M26: YES | N26: รีโมท | O26: เรียบร้อยปกติ | P26: โมชิ | S26: เกิดจากการตั้งกำหนดเวลาเล่นสื่อของทีมขึ้นสื่อ คือตั้งกำหนดหมดอายุ สิ้นเดือน สิงหาคม | T26: ยกเลิกกำหนดเวลาในโปรแกรม และส่งสื่อขึ้นจอให้ใหม่ | U26: แก้ไขสื่อ | W26: 45536.444 | Y26: =ROUND(IF(ISBLANK(W26), (NOW() - D26) * 24 / 24, (W26 - D26) * 24 / 24), 2) & " วัน " & ROUND(MOD(IF(ISBLANK(W26), (NOW() - D26) * 24, (W26 - D26) * 24), 24), 2) & " ชั่วโมง" -> 0 วัน 0 ชั่วโมง | AB26: TR0024
A27: 26 | B27: 7317214 | C27: ไลน์ | D27: 45536.449 | E27: =UPPER(LEFT(F27,3))&TEXT(COUNTA($F$2:F27),"000000") -> TRU000026 | F27: TRUE | G27: True Branding Shop Central Embassy | I27: ศวิตา | J27: 0842974646 | K27: จอ ดับ2จอ ครับ | M27: YES | N27: รีโมท | O27: เรียบร้อยปกติ | P27: โมชิ | S27: เกิดจากการตั้งกำหนดเวลาเล่นสื่อของทีมขึ้นสื่อ คือตั้งกำหนดหมดอายุ สิ้นเดือน สิงหาคม | T27: ยกเลิกกำหนดเวลาในโปรแกรม และส่งสื่อขึ้นจอให้ใหม่ | U27: แก้ไขสื่อ | W27: 45536.449 | Y27: =ROUND(IF(ISBLANK(W27), (NOW() - D27) * 24 / 24, (W27 - D27) * 24 / 24), 2) & " วัน " & ROUND(MOD(IF(ISBLANK(W27), (NOW() - D27) * 24, (W27 - D27) * 24), 24), 2) & " ชั่วโมง" -> 0 วัน 0 ชั่วโมง | AB27: TR0025
A28: 27 | B28: 7317215 | C28: ไลน์ | D28: 45536.455 | E28: =UPPER(LEFT(F28,3))&TEXT(COUNTA($F$2:F28),"000000") -> TRU000027 | F28: TRUE | G28: True Shop The Mall Bangkapi | I28: Nittaya | J28: 0893545982 | K28: จอไม่โชว์สื่อ(ระบบสัญญาณ)/จอไม่ติดค่ะ ขึ้นแสดงLogo แล้วดับไป เอกสารตามไฟล์แนบ | M28: YES | N28: รีโมท | O28: เรียบร้อยปกติ | P28: โมชิ | S28: เกิดจากการตั้งกำหนดเวลาเล่นสื่อของทีมขึ้นสื่อ คือตั้งกำหนดหมดอายุ สิ้นเดือน สิงหาคม | T28: ยกเลิกกำหนดเวลาในโปรแกรม และส่งสื่อขึ้นจอให้ใหม่ | U28: แก้ไขสื่อ | W28: 45536.455 | Y28: =ROUND(IF(ISBLANK(W28), (NOW() - D28) * 24 / 24, (W28 - D28) * 24 / 24), 2) & " วัน " & ROUND(MOD(IF(ISBLANK(W28), (NOW() - D28) * 24, (W28 - D28) * 24), 24), 2) & " ชั่วโมง" -> 0 วัน 0 ชั่วโมง | AB28: TR0026
A29: 28 | B29: 7318459 | C29: ไลน์ | D29: 45537.387 | E29: =UPPER(LEFT(F29,3))&TEXT(COUNTA($F$2:F29),"000000") -> TRU000028 | F29: TRUE | G29: True Shop Central Nakhonsawan | I29: สุรศักดิ์ | J29: 0858333337 | K29: เนื่องจากทางสาขามีการติดตั้ง wall samsung ใหม่ รบกวน หน่วยงาน แก้ไข สื่อช่อง ตามแจ้ง เป็น samsung | M29: YES | N29: รีโมท | O29: เรียบร้อยปกติ | P29: โมชิ | S29: เกิดจากการตั้งกำหนดเวลาเล่นสื่อของทีมขึ้นสื่อ คือตั้งกำหนดหมดอายุ สิ้นเดือน สิงหาคม | T29: ยกเลิกกำหนดเวลาในโปรแกรม และส่งสื่อขึ้นจอให้ใหม่ | U29: แก้ไขสื่อ | W29: 45537.387 | Y29: =ROUND(IF(ISBLANK(W29), (NOW() - D29) * 24 / 24, (W29 - D29) * 24 / 24), 2) & " วัน " & ROUND(MOD(IF(ISBLANK(W29), (NOW() - D29) * 24, (W29 - D29) * 24), 24), 2) & " ชั่วโมง" -> 0 วัน 0 ชั่วโมง | AB29: TR0027
A30: 29 | B30: 7329061 | C30: ไลน์ | D30: 45539.503 | E30: =UPPER(LEFT(F30,3))&TEXT(COUNTA($F$2:F30),"000000") -> TRU000029 | F30: TRUE | G30: True Shop Central Chanthaburi | I30: Nitipat | J30: 0830748330 | K30: ต้องการให้สลับหน้าจอ Wall มาให้ตรงกับ Wall Samsung | M30: YES | N30: รีโมท | O30: เรียบร้อยปกติ | P30: โมชิ | S30: เกิดจากการจัดชั้นวางสินค้าซ้าย ขวา ของทางหน้าร้าน กับทีมขึันสื่อเรา เนื่องจากไม่มีรูปประกอบ ตั้งแต่แรกที่มีแจ้งเพิ่มสินค้าในชั้นวาง | T30: สลับสื่อขึ้นจอให้ลูกค้าใหม่ | U30: แก้ไขสื่อ | W30: 45539.503 | Y30: =ROUND(IF(ISBLANK(W30), (NOW() - D30) * 24 / 24, (W30 - D30) * 24 / 24), 2) & " วัน " & ROUND(MOD(IF(ISBLANK(W30), (NOW() - D30) * 24, (W30 - D30) * 24), 24), 2) & " ชั่วโมง" -> 0 วัน 0 ชั่วโมง | AB30: TR0028
A31: 30 | B31: 7329317 | C31: ไลน์ | D31: 45541.535 | E31: =UPPER(LEFT(F31,3))&TEXT(COUNTA($F$2:F31),"000000") -> TRU000030 | F31: TRUE | G31: True Shop Seacon Square 2 | I31: Chutima | J31: 0955965646 | K31: จอ สื่ออัพเดทสลับกัน | M31: YES | N31: รีโมท | O31: เรียบร้อยปกติ | P31: โมชิ | S31: เกิดจากการจัดชั้นวางสินค้าซ้าย ขวา ของทางหน้าร้าน กับทีมขึันสื่อเรา เนื่องจากไม่มีรูปประกอบ ตั้งแต่แรกที่มีแจ้งเพิ่มสินค้าในชั้นวาง | T31: สลับสื่อขึ้นจอให้ลูกค้าใหม่ | U31: แก้ไขสื่อ | W31: 45541.535 | Y31: =ROUND(IF(ISBLANK(W31), (NOW() - D31) * 24 / 24, (W31 - D31) * 24 / 24), 2) & " วัน " & ROUND(MOD(IF(ISBLANK(W31), (NOW() - D31) * 24, (W31 - D31) * 24), 24), 2) & " ชั่วโมง" -> 0 วัน 0 ชั่วโมง | AB31: TR0029
A32: 31 | B32: 7331177 | C32: ไลน์ | D32: 45542.511 | E32: =UPPER(LEFT(F32,3))&TEXT(COUNTA($F$2:F32),"000000") -> TRU000031 | F32: TRUE | G32: True Shop Central Festival Samui | I32: Pornchanok | J32: 0653632157 / 0956619797 | K32: จอดับบางส่วน | M32: YES | N32: รีโมท | O32: เรียบร้อยปกติ | P32: โมชิ | S32: เกิดจากการอ่านทำความเข้าใจของทีมขึ้นสื่อเราเข้าใจผิด เลยทำให้ขึ้นสื่อผิดพลาด รบกวนอัพเดทสื่อเฉพาะ baseud ให้แก่สาขาด้วย | T32: อัพเดตสื่อขึ้นจอให้ลูกค้าใหม่ | U32: แก้ไขสื่อ | W32: 45542.511 | Y32: =ROUND(IF(ISBLANK(W32), (NOW() - D32) * 24 / 24, (W32 - D32) * 24 / 24), 2) & " วัน " & ROUND(MOD(IF(ISBLANK(W32), (NOW() - D32) * 24, (W32 - D32) * 24), 24), 2) & " ชั่วโมง" -> 0 วัน 0 ชั่วโมง | AB32: TR0030
A33: 32 | C33: ไลน์ | D33: 45546.681 | E33: =UPPER(LEFT(F33,3))&TEXT(COUNTA($F$2:F33),"000000") -> TRU000032 | F33: TRUE | G33: True Shop Central Nakhonsawan | K33: สื่อ 5G Cash Back ไม่ขึ้น รบกวนดำเนินการตรวจสอบ | M33: YES | N33: รีโมท | O33: เรียบร้อยปกติ | P33: โมชิ | S33: เกิดจากการตกหล่นในการส่งขึ้นสื่อ | T33: อัพเดตสื่อขึ้นจอให้ลูกค้าใหม่ | U33: แก้ไขสื่อ | W33: 45546.701 | Y33: =ROUND(IF(ISBLANK(W33), (NOW() - D33) * 24 / 24, (W33 - D33) * 24 / 24), 2) & " วัน " & ROUND(MOD(IF(ISBLANK(W33), (NOW() - D33) * 24, (W33 - D33) * 24), 24), 2) & " ชั่วโมง" -> 0.02 วัน 0.5 ชั่วโมง
A34: 33 | C34: ไลน์ | D34: 45546.681 | E34: =UPPER(LEFT(F34,3))&TEXT(COUNTA($F$2:F34),"000000") -> TRU000033 | F34: TRUE | G34: True Shop Central mahachai | K34: สื่อ 5G Cash Back ไม่ขึ้น รบกวนดำเนินการตรวจสอบ | M34: YES | N34: รีโมท | O34: เรียบร้อยปกติ | P34: โมชิ | S34: เกิดจากการตกหล่นในการส่งขึ้นสื่อ | T34: อัพเดตสื่อขึ้นจอให้ลูกค้าใหม่ | U34: แก้ไขสื่อ | W34: 45546.701 | Y34: =ROUND(IF(ISBLANK(W34), (NOW() - D34) * 24 / 24, (W34 - D34) * 24 / 24), 2) & " วัน " & ROUND(MOD(IF(ISBLANK(W34), (NOW() - D34) * 24, (W34 - D34) * 24), 24), 2) & " ชั่วโมง" -> 0.02 วัน 0.5 ชั่วโมง
A35: 34 | B35: 7338421 | C35: ไลน์ | D35: 45546.681 | E35: =UPPER(LEFT(F35,3))&TEXT(COUNTA($F$2:F35),"000000") -> TRU000034 | F35: TRUE | G35: True Shop Central Plaza Ramindra | I35: Chayapon | J35: 0809719995 | K35: สื่อ 5G Cash Back ไม่ขึ้น รบกวนดำเนินการตรวจสอบ | M35: YES | N35: รีโมท | O35: เรียบร้อยปกติ | P35: โมชิ | S35: เกิดจากการตกหล่นในการส่งขึ้นสื่อ | T35: อัพเดตสื่อขึ้นจอให้ลูกค้าใหม่ | U35: แก้ไขสื่อ | W35: 45546.701 | Y35: =ROUND(IF(ISBLANK(W35), (NOW() - D35) * 24 / 24, (W35 - D35) * 24 / 24), 2) & " วัน " & ROUND(MOD(IF(ISBLANK(W35), (NOW() - D35) * 24, (W35 - D35) * 24), 24), 2) & " ชั่วโมง" -> 0.02 วัน 0.5 ชั่วโมง
A36: 35 | B36: 7338555 | C36: ไลน์ | D36: 45546.681 | E36: =UPPER(LEFT(F36,3))&TEXT(COUNTA($F$2:F36),"000000") -> TRU000035 | F36: TRUE | G36: True Shop Ayudhaya Park | I36: พลลภัตม์ | J36: 0840184148 | K36: สื่อ 5G Cash Back ไม่ขึ้น รบกวนดำเนินการตรวจสอบ | M36: YES | N36: รีโมท | O36: เรียบร้อยปกติ | P36: โมชิ | S36: เกิดจากการตกหล่นในการส่งขึ้นสื่อ | T36: อัพเดตสื่อขึ้นจอให้ลูกค้าใหม่ | U36: แก้ไขสื่อ | W36: 45546.701 | Y36: =ROUND(IF(ISBLANK(W36), (NOW() - D36) * 24 / 24, (W36 - D36) * 24 / 24), 2) & " วัน " & ROUND(MOD(IF(ISBLANK(W36), (NOW() - D36) * 24, (W36 - D36) * 24), 24), 2) & " ชั่วโมง" -> 0.02 วัน 0.5 ชั่วโมง
A37: 36 | B37: 7338559 | C37: ไลน์ | D37: 45546.681 | E37: =UPPER(LEFT(F37,3))&TEXT(COUNTA($F$2:F37),"000000") -> TRU000036 | F37: TRUE | G37: True Shop Imperial World Samrong | I37: Sudarat | J37: 0955959399 | K37: สื่อ 5G Cash Back ไม่ขึ้น รบกวนดำเนินการตรวจสอบ | M37: YES | N37: รีโมท | O37: เรียบร้อยปกติ | P37: โมชิ | S37: เกิดจากอาการจอกล่องควบคุมจอค้าง | T37: รีสตาร์ทกล่อง Imperial World Samrong จอติดเรียบร้อย | U37: แก้ไขสื่อ | W37: 45546.701 | Y37: =ROUND(IF(ISBLANK(W37), (NOW() - D37) * 24 / 24, (W37 - D37) * 24 / 24), 2) & " วัน " & ROUND(MOD(IF(ISBLANK(W37), (NOW() - D37) * 24, (W37 - D37) * 24), 24), 2) & " ชั่วโมง" -> 0.02 วัน 0.5 ชั่วโมง
A38: 37 | B38: 7338576 | C38: ไลน์ | D38: 45546.681 | E38: =UPPER(LEFT(F38,3))&TEXT(COUNTA($F$2:F38),"000000") -> TRU000037 | F38: TRUE | G38: True Shop Central Westville | I38: กนกลักษณ์ | J38: 0647895971 | K38: สื่อ 5G Cash Back ไม่ขึ้น รบกวนดำเนินการตรวจสอบ | M38: YES | N38: รีโมท | O38: เรียบร้อยปกติ | P38: โมชิ | S38: เกิดจากการตกหล่นในการส่งขึ้นสื่อ | T38: อัพเดตสื่อขึ้นจอให้ลูกค้าใหม่ | U38: แก้ไขสื่อ | W38: 45546.701 | Y38: =ROUND(IF(ISBLANK(W38), (NOW() - D38) * 24 / 24, (W38 - D38) * 24 / 24), 2) & " วัน " & ROUND(MOD(IF(ISBLANK(W38), (NOW() - D38) * 24, (W38 - D38) * 24), 24), 2) & " ชั่วโมง" -> 0.02 วัน 0.5 ชั่วโมง
A39: 38 | C39: ไลน์ | D39: 45546.701 | E39: =UPPER(LEFT(F39,3))&TEXT(COUNTA($F$2:F39),"000000") -> NEW000038 | F39: Newlook | G39: Adidas เซ็นทรัลปิ่นเกล้า | K39: จอดับบางส่วน | M39: YES | N39: แก้ไขหน้างาน | O39: เรียบร้อยปกติ | P39: โมชิ | S39: Recive มีปัญหา | T39: ทำการเปลี่ยน Card Recive และทำการย้ำหัวสายแลนใหม่ ทั้งหัวท้าย | U39: Recive | W39: 45558.533 | Y39: =ROUND(IF(ISBLANK(W39), (NOW() - D39) * 24 / 24, (W39 - D39) * 24 / 24), 2) & " วัน " & ROUND(MOD(IF(ISBLANK(W39), (NOW() - D39) * 24, (W39 - D39) * 24), 24), 2) & " ชั่วโมง" -> 11.83 วัน 19.95 ชั่วโมง | AB39: NE0037
A40: 39 | C40: ไลน์ | D40: 45534 | E40: =UPPER(LEFT(F40,3))&TEXT(COUNTA($F$2:F40),"000000") -> TRU000039 | F40: TRUE | G40: True Shop Central Westville | K40: สื่อ 5G Cash Back ไม่ขึ้น รบกวนดำเนินการตรวจสอบ | M40: YES | N40: รีโมท | O40: เรียบร้อยปกติ | P40: โมชิ | S40: เกิดจากการตกหล่นในการส่งขึ้นสื่อ | T40: อัพเดตสื่อขึ้นจอให้ลูกค้าใหม่ | U40: แก้ไขสื่อ | W40: 45546.681 | Y40: =ROUND(IF(ISBLANK(W40), (NOW() - D40) * 24 / 24, (W40 - D40) * 24 / 24), 2) & " วัน " & ROUND(MOD(IF(ISBLANK(W40), (NOW() - D40) * 24, (W40 - D40) * 24), 24), 2) & " ชั่วโมง" -> 12.68 วัน 16.33 ชั่วโมง
...

Sheet ใบงานช่าง
F2: SERVICE REPORT | I2: หัวบริษัท
B4: ชื่องาน: | C4: =VLOOKUP(G6,DataServiceDR!E:AB,2,0) -> TRUE | D4: =VLOOKUP(G6,DataServiceDR!E:V,3,0) -> TS Terminal 21 Pattaya | F4: วันที่นัดหมาย: | G4: =VLOOKUP(G6,DataServiceDR!E:AB,13,0) -> 0
B5: ชื่อลูกค้า: | C5: =VLOOKUP(G6,DataServiceDR!E:AB,5,0) -> 0 | F5: เบอร์โทรติดต่อลูกค้า: | G5: =VLOOKUP(G6,DataServiceDR!E:AB,6,0) -> 0
B6: ช่องทางการแจ้งซ่อม: | F6: เลขที่ติดตาม: | G6: TRU000458
B8: อาการที่ได้รับแจ้ง: | D8: =VLOOKUP(G6,DataServiceDR!E:AB,7,0) -> งานขึ้นสื่อ ทรู สื่อ Apple Sheep เพิ่มเติมจาก
B9: =VLOOKUP(G6,DataServiceDR!E:AB,15,0) -> อัพสื่อเพิ่มเติมเ
B12: รูปอาการ : | F12: ผลการตรวจสอบ:
K13: Person In Charge
K14: Company:Bangkok Metro Networks Limited
K15: Item | L15: Thai Name | M15: Nick Name | N15: English Name | O15: Badge ID NO | P15: ประเภทบัตร | Q15: Expiry Date (PIC) | R15: Expiry Date (APOSTLE)
K16: 1 | L16: นายธเนศ ประจำแท่น | M16: ฟู | N16: Mr.Thanet Prachamthan | O16: BMN-P1221 | P16: PIC(HI,CE) | Q16: 24776 | R16: DR
F17: วิธีแก้ไข: | K17: 2 | L17: นายวีรชยน สมร | M17: จ่อย | N17: mr.Virachon Som | O17: BMN-P1218 | P17: PIC(HI,CE) | Q17: 24776 | R17: DR
K18: 3 | L18: นายวัฒนชัย อ่อนไธสง | M18: ศักดิ์ | N18: Mr.Wattananchai Onthaisong | O18: BMN-P1394 | P18: PIC(HI,CE) | Q18: 24776 | R18: DR
K19: 4 | L19: นายสามารถ ยาวิราช | M19: เหน่ง | N19: Mr.Samart Yawirach | O19: BMN-P1935 | P19: PIC(HI,CE,SCAF) | Q19: 24776 | R19: DR
K20: 5 | L20: ธงชัย ทองนิยม | N20: Mr.Thongchai thongniyom | O20: BMN-P1936 | P20: PIC(HI,CE,SCAF) | Q20: 24776 | R20: IDIO
K21: 6 | L21: นายวินัย สุโพธิ์ | N21: Mr.Vinai Supho | O21: BMN-P1937 | P21: PIC(HI,CE,SCAF) | Q21: 24776 | R21: IDIO
F22: ผลการแก้ไข: | K22: 7 | L22: นายวาฤทธิ์ แแก้วพิลส | N22: Mr.Waarit Keawpila | O22: BMN-P1938 | P22: PIC | Q22: 24411 | R22: IDIO | S22: รออบรม
K23: 8 | L23: นายศรายุทธ์ บางต่าย | N23: Mr.Sarayut Bangtai | O23: BMN-P1939 | P23: PIC | Q23: 24776 | R23: IDIO
K24: 9 | L24: นายนัทธพงส์ หมื่นศรี | N24: Mr.Nuttapong Muensri | O24: BMN-P1940 | P24: PIC | Q24: 24776 | R24: IDIO
L25: นายอติชาติ สอนโก่ย | N25: Mr.Atchart Sonkoi | O25: BMN-P1941 | P25: PIC | Q25: 24411 | R25: IDIO | S25: รออบรม
B26: รายชื่อช่าง: | C26: =VLOOKUP(G6,DataServiceDR!E:V,12,0) -> 0 | K26: 11 | L26: นายเกษม ประจำแท่น | M26: เตอร์ | N26: Mr.kasem Prachamthan | O26: BMN-P1948 | P26: PIC(HI,CE,SCAF) | Q26: 24776 | R26: DR
K27: 12 | L27: นายอนุวัต พ่วงชู | N27: Mr.Anuwat Poungchu | O27: BMN-P2054 | P27: PIC | Q27: 25142 | R27: IDIO
B28: ข้อเสนอแนะ: | K28: 13 | L28: นายไตรรัตน์ ปีกลาง | M28: นิค | N28: Mr.Trairat Peklang | O28: BMN-P2074 | P28: PIC(HI,CE,SCAF) | Q28: 25142 | R28: DR | S28: เพิ่มเปิดฝ้า
K29: 14 | L29: นายปรีชา ภูตานันท์ | M29: ชา | N29: Mr.Peecha Phootanan | O29: BMN-P2145 | P29: PIC | Q29: 24776 | R29: DR
L31: นายชินาธิป สุขธูป.jpg | M31: เณน
L32: นายปรีชา ภูตานันท์.jpg | M32: ชาสลิม
C33: ลงชื่อ | F33: ลงชื่อ | L33: นายณัฐวุฒิ อรรถประจง.jpg | M33: โอ๋
L34: นายสามารถ ยาวิราช.jpg | M34: เหน่ง 0625937779
B35: (..................................................................) | F35: (..................................................................) | L35: นายสุเมธ อะวะรัมย์.jpg | M35: แบงค์
C36: ช่างตรวจสอบแก้ไข | F36: ผู้ตรวจรับงาน | L36: นายเกรียงไกร นักธรรม.jpg | M36: นุ๊ก
L37: นายวุฒิพงษ์ สีใส.jpg | M37: มาร์ค
L38: นายบัญชา ทองโสม.jpg | M38: เอ้

Sheet Service แจ้งไลน์
D1: 1 | E1: 2 | F1: 3 | G1: 4 | H1: 5 | I1: 6 | J1: 7 | K1: 8 | L1: 9 | M1: 10 | N1: 11 | O1: 12 | P1: 13 | Q1: 14 | R1: 15 | S1: 16 | T1: 17 | U1: 18 | V1: 19 | W1: 20
E2: ข้อมูลลูกค้า | J2: ข้อมูลสินค้า | L2: การดำเนินการ | O2: รายละเอียดข้อมูล | Q2: วันเวลานัดหมาย
A3: Ref. | B3: จาก | C3: วันเวลาที่แจ้ง | D3: Tk NO. | E3: ลูกค้า | F3: สถานที่/สาขา | G3: ผู้ติดต่อ | H3: เบอร์โทร | I3: ข้อมูลการรับแจ้ง | J3: สินค้า/บริการ | K3: เงือนไข MA | L3: ลักษณะงาน | M3: สถานะงาน | N3: ผู้ดำเนินการ | O3: ผลการตรวจสอบ | P3: วิธีแก้ไข | Q3: วันเวลาเริ่ม | R3: วันเวลาสิ้นสุด | S3: วันเวลาเสร็จ | T3: วัน/ชั่วโมง ที่ใช้ | U3: หมายเหตุ | V3: ทะเบียนรถ | W3: ไฟล์
A5: 1.แจ้งเปิดเคสในกลุ่มลูกค้า
A6: ขออภัยในความไม่สะดวกที่เกิดขึ้น
A7: ทางทีมงานขอรับเรื่องไว้และรีบดำเนินการให้ครับ
A8: ขออนุญาตแจ้งเลขติดตามงาน: | B8: MA0210
A9: ลูกค้า: | B9: =VLOOKUP(B8,DataServiceDR!E:Y,2,0) -> #N/A
A10: สถานที่/สาขา: | B10: =VLOOKUP(B8,DataServiceDR!E:Y,3,0) -> #N/A
A11: ผู้ติดต่อ: | B11: =VLOOKUP(B8,DataServiceDR!E:Y,4,0) -> #N/A
A12: เบอร์โทร: | B12: =VLOOKUP(B8,DataServiceDR!E:Y,5,0) -> #N/A
A13: ข้อมูลการรับแจ้ง: | B13: =VLOOKUP(B8,DataServiceDR!E:Y,6,0) -> #N/A
A14: สถานะงาน: | B14: =VLOOKUP(B8,DataServiceDR!E:Y,10,0) -> #N/A
A15: @ลูกค้า
A17: 2.แจ้งงานส่งต่อในกลุ่ม Digital Signage Operation
A18: ขออนุญาตแจ้งเลขติดตามงาน: | B18: =B8 -> MA0210
A19: ลูกค้า: | B19: =VLOOKUP(B18,DataServiceDR!E:Y,2,0) -> #N/A
A20: สถานที่/สาขา: ไอคอนสยาม | B20: =VLOOKUP(B18,DataServiceDR!E:Y,3,0) -> #N/A
A21: ผู้ติดต่อ: | B21: =VLOOKUP(B18,DataServiceDR!E:Y,4,0) -> #N/A
A22: เบอร์โทร: | B22: =VLOOKUP(B18,DataServiceDR!E:Y,5,0) -> #N/A
A23: ข้อมูลการรับแจ้ง: | B23: =VLOOKUP(B18,DataServiceDR!E:Y,6,0) -> #N/A
A24: รายละเอียดข้อมูล: ex.เนื่องจากหมดอายุประกันแล้วรบกวนทำใบเสนอราคารายการดังนี้ | B24: =VLOOKUP(B18,DataServiceDR!E:Y,12,0) -> #N/A
A25: สถานะงาน: | B25: =VLOOKUP(B8,DataServiceDR!E:Y,10,0) -> #N/A
A26: @S🦋 @DR Sale Coordinator @Mac @j-pan & j-day
A28: 3.แจ้งงานส่งต่อกลุ่ม ขอ PR สั่งซื้อ
A29: ขออนุญาตแจ้งเลขติดตามงาน: | B29: =B8 -> MA0210
A30: ลูกค้า: | B30: =VLOOKUP(B18,DataServiceDR!E:Y,2,0) -> #N/A
A31: สถานที่/สาขา: | B31: =VLOOKUP(B29,DataServiceDR!E:Y,3,0) -> #N/A
A32: ผู้ติดต่อ: | B32: =VLOOKUP(B29,DataServiceDR!E:Y,4,0) -> #N/A
A33: เบอร์โทร: | B33: =VLOOKUP(B29,DataServiceDR!E:Y,5,0) -> #N/A
A34: ข้อมูลการรับแจ้ง: | B34: =VLOOKUP(B18,DataServiceDR!E:Y,6,0) -> #N/A
A35: รายละเอียดข้อมูล: | B35: =VLOOKUP(B18,DataServiceDR!E:Y,12,0) -> #N/A
A36: สถานะงาน: | B36: =VLOOKUP(B18,DataServiceDR!E:Y,10,0) -> #N/A
A37: @DR-จัดซื้อ (เรย์) @DR จัดซื้อ (ทราย) @Lyn🐷Tiney🐰Thamma
A39: 4.แจ้งขอคิวช่างเข้าดำเนินการ ในกลุ่มDRปรึกษาการเข้างาน
A40: ขออนุญาตแจ้งเลขติดตามงาน: | B40: =B8 -> MA0210
A41: ลูกค้า: | B41: =VLOOKUP(B18,DataServiceDR!E:Y,2,0) -> #N/A
A42: สถานที่/สาขา: | B42: =VLOOKUP(B18,DataServiceDR!E:Y,3,0) -> #N/A
A43: ข้อมูลการรับแจ้ง: | B43: =VLOOKUP(B18,DataServiceDR!E:Y,6,0) -> #N/A
A44: สถานะงาน: | B44: =VLOOKUP(B18,DataServiceDR!E:Y,10,0) -> #N/A
...
